<?xml version="1.0"?>
<robot xmlns:xacro="http://www.ros.org/wiki/xacro">

  <xacro:macro name="iiwa_no_material" params="parent prefix *origin">
  <!-- Andiamo a definire la base del robot(prefix è un parametro che verra passato da dual_iiwa_robot per la costruzione del robot complessivo ) -->
  <link name="${prefix}iiwa_base" type="fixed"/>
  <!-- Vado a definire il giunto che lega la spalla che può essere sinistra o destra con la base del manipolatore destro o sinistro-->
  <joint name="${prefix}iiwa_root_joint" type="fixed">
      <xacro:insert_block name="origin" />
      <parent link="${parent}"/>
      <child link="${prefix}iiwa_base"/>
  </joint>

  <joint name="${prefix}iiwa_base_joint" type="fixed">
      <origin rpy="0.0 0 0" xyz="0 0 0"/>
      <parent link="${prefix}iiwa_base"/>
      <child link="${prefix}link_0"/>
  </joint>

  <link name="${prefix}link_0">
      <visual>
        <origin rpy="0.0 0 0" xyz="0 0 0"/>
        <geometry>
          <mesh filename="file://$(find iiwa_description)/meshes/lbr_iiwa_14_r820/visual/base_link.dae"/>
        </geometry>
      </visual>
      <collision>
        <origin rpy="0 0 0" xyz="0 0 0"/>
        <geometry>
          <mesh filename="file://$(find iiwa_description)/meshes/lbr_iiwa_14_r820/collision/base_link.stl"/>
        </geometry>
      </collision>
      <inertial>
        <origin xyz="-0.1 0 0.07" rpy="0 0 0"/>
        <mass value="5"/>
        <inertia ixx="0.05"  ixy="0"  ixz="0" iyy="0.06" iyz="0" izz="0.03" />
      </inertial>
  </link>
  <link name="${prefix}link_1">
      <visual>
        <origin rpy="0 0 0" xyz="0 0 0"/>
        <geometry>
          <mesh filename="file://$(find iiwa_description)/meshes/lbr_iiwa_14_r820/visual/link_1.dae"/>
        </geometry>
      </visual>
      <collision>
        <origin rpy="0 0 0" xyz="0 0 0"/>
        <geometry>
          <mesh filename="file://$(find iiwa_description)/meshes/lbr_iiwa_14_r820/collision/link_1.stl"/>
        </geometry>
      </collision>
      <inertial>
        <origin xyz="0 -0.03 0.12" rpy="0 0 0"/>
        <mass value="4"/>
        <inertia ixx="0.1"  ixy="0"  ixz="0" iyy="0.09" iyz="0" izz="0.02" />
      </inertial>
  </link>
  <link name="${prefix}link_2">
      <visual>
        <origin rpy="0 0 0" xyz="0 0 0"/>
        <geometry>
          <mesh filename="file://$(find iiwa_description)/meshes/lbr_iiwa_14_r820/visual/link_2.dae"/>
        </geometry>
      </visual>
      <collision>
        <origin rpy="0 0 0" xyz="0 0 0"/>
        <geometry>
          <mesh filename="file://$(find iiwa_description)/meshes/lbr_iiwa_14_r820/collision/link_2.stl"/>
        </geometry>
      </collision>
      <inertial>
        <origin xyz="0.0003 0.059 0.042" rpy="0 0 0"/>
        <mass value="4"/>
        <inertia ixx="0.05"  ixy="0"  ixz="0" iyy="0.018" iyz="0" izz="0.044" />
      </inertial>
  </link>
  <link name="${prefix}link_3">
      <visual>
        <origin rpy="0 0 0" xyz="0 0 0"/>
        <geometry>
          <mesh filename="file://$(find iiwa_description)/meshes/lbr_iiwa_14_r820/visual/link_3.dae"/>
        </geometry>
      </visual>
      <collision>
        <origin rpy="0 0 0" xyz="0 0 0"/>
        <geometry>
          <mesh filename="file://$(find iiwa_description)/meshes/lbr_iiwa_14_r820/collision/link_3.stl"/>
        </geometry>
      </collision>
      <inertial>
        <origin xyz="0 0.03 0.13" rpy="0 0 0"/>
        <mass value="3"/>
        <inertia ixx="0.08"  ixy="0"  ixz="0" iyy="0.075" iyz="0" izz="0.01" />
      </inertial>
  </link>
  <link name="${prefix}link_4">
      <visual>
        <origin rpy="0 0 0" xyz="0 0 0"/>
        <geometry>
          <mesh filename="file://$(find iiwa_description)/meshes/lbr_iiwa_14_r820/visual/link_4.dae"/>
        </geometry>
      </visual>
      <collision>
        <origin rpy="0 0 0" xyz="0 0 0"/>
        <geometry>
          <mesh filename="file://$(find iiwa_description)/meshes/lbr_iiwa_14_r820/collision/link_4.stl"/>
        </geometry>
      </collision>
      <inertial>
        <origin xyz="0 0.067 0.034" rpy="0 0 0"/>
        <mass value="2.7"/>
        <inertia ixx="0.03"  ixy="0"  ixz="0" iyy="0.01" iyz="0" izz="0.029" />
      </inertial>
  </link>
  <link name="${prefix}link_5">
      <visual>
        <origin rpy="0 0 0" xyz="0 0 0"/>
        <geometry>
          <mesh filename="file://$(find iiwa_description)/meshes/lbr_iiwa_14_r820/visual/link_5.dae"/>
        </geometry>
      </visual>
      <collision>
        <origin rpy="0 0 0" xyz="0 0 0"/>
        <geometry>
          <mesh filename="file://$(find iiwa_description)/meshes/lbr_iiwa_14_r820/collision/link_5.stl"/>
        </geometry>
      </collision>
      <inertial>
        <origin xyz="0.0001 0.021 0.076" rpy="0 0 0"/>
        <mass value="1.7"/>
        <inertia ixx="0.02"  ixy="0"  ixz="0" iyy="0.018" iyz="0" izz="0.005" />
      </inertial>
  </link>
  <link name="${prefix}link_6">
      <visual>
        <origin rpy="0 0 0" xyz="0 0 0"/>
        <geometry>
          <mesh filename="file://$(find iiwa_description)/meshes/lbr_iiwa_14_r820/visual/link_6.dae"/>
        </geometry>
      </visual>
      <collision>
        <origin rpy="0 0 0" xyz="0 0 0"/>
        <geometry>
          <mesh filename="file://$(find iiwa_description)/meshes/lbr_iiwa_14_r820/collision/link_6.stl"/>
        </geometry>
      </collision>
      <inertial>
        <origin xyz="0 0.0006 0.0004" rpy="0 0 0"/>
        <mass value="1.8"/>
        <inertia ixx="0.025"  ixy="0"  ixz="0" iyy="0.0136" iyz="0" izz="0.0247" />
      </inertial>
  </link>
  
  <link name="${prefix}link_7">
      <visual>
        <origin rpy="0 0 0" xyz="0 0 0.07"/>
        <material name="gray"/>
        <geometry>
          <mesh filename="file://$(find iiwa_description)/meshes/lbr_iiwa_14_r820/visual/link_7_2.stl" scale ="0.001 0.001 0.001"/>
        </geometry>
      </visual>
      <collision>
        <origin rpy="0 0 0" xyz="0 0 0.07"/>
        <geometry>
          <mesh filename="file://$(find iiwa_description)/meshes/lbr_iiwa_14_r820/collision/link_7_2.stl" scale ="0.001 0.001 0.001"/>
        </geometry>
      </collision>
      <inertial>
        <origin xyz="0 0 0.02" rpy="0 0 0"/>
        <mass value="${0.3 / 0.308 * 0.44}"/> <!--this is for the MFT Pneumatisch flange-->
        <inertia ixx="0.01"  ixy="0"  ixz="0" iyy="0.01" iyz="0" izz="0.01" />
      </inertial>
  </link>
  
  <!-- intermediate tool0 link to make hand pose tunable -->
  <link name="${prefix}tool0"/>

    <link name="${prefix}tcp">
    <visual>
      <origin xyz="0 0 0" rpy="0 0 0"/>
      <geometry>
        <!-- SCHUNK end-effector mesh (file present in meshes/) -->
          <mesh filename="file://$(find iiwa_description)/meshes/schunk.stl" scale ="0.001 0.001 0.001"/>
      </geometry>
    </visual>
    <collision>
      <origin xyz="0 0 0" rpy="0 0 0"/>
      <geometry>
          <mesh filename="file://$(find iiwa_description)/meshes/schunk.stl" scale ="0.001 0.001 0.001"/>
      </geometry>
    </collision>
    <inertial>
      <origin xyz="0 0 0" rpy="0 0 0"/>
      <mass value="0.5"/>
      <inertia ixx="0.0" ixy="0.0" ixz="0.0" iyy="0.0" iyz="0.0" izz="0.0"/>
    </inertial>
  </link>
  <joint name="${prefix}joint_a1" type="revolute">
      <origin rpy="0 0 0" xyz="0 0 0"/>
      <parent link="${prefix}link_0"/>
      <child link="${prefix}link_1"/>
      <axis xyz="0 0 1"/>
      <limit effort="320" lower="-2.9668" upper="2.9668" velocity="1.4834"/>
  </joint>
  <joint name="${prefix}joint_a2" type="revolute">
      <origin rpy="0 0 0" xyz="-0.00043624 0 0.36"/>
      <parent link="${prefix}link_1"/>
      <child link="${prefix}link_2"/>
      <axis xyz="0 1 0"/>
      <limit effort="320" lower="-2.0942" upper="2.0942" velocity="1.4834"/>
  </joint>
  <joint name="${prefix}joint_a3" type="revolute">
      <origin rpy="0 0 0" xyz="0 0 0"/>
      <parent link="${prefix}link_2"/>
      <child link="${prefix}link_3"/>
      <axis xyz="0 0 1"/>
      <limit effort="176" lower="-2.9668" upper="2.9668" velocity="1.7452"/>
  </joint>
  <joint name="${prefix}joint_a4" type="revolute">
      <origin rpy="0 0 0" xyz="0.00043624 0 0.42"/>
      <parent link="${prefix}link_3"/>
      <child link="${prefix}link_4"/>
      <axis xyz="0 -1 0"/>
      <limit effort="176" lower="-2.0942" upper="2.0942" velocity="1.3089"/>
  </joint>
  <joint name="${prefix}joint_a5" type="revolute">
      <origin rpy="0 0 0" xyz="0 0 0"/>
      <parent link="${prefix}link_4"/>
      <child link="${prefix}link_5"/>
      <axis xyz="0 0 1"/>
      <limit effort="110" lower="-2.9668" upper="2.9668" velocity="2.2688"/>
  </joint>
  <joint name="${prefix}joint_a6" type="revolute">
      <origin rpy="0 0 0" xyz="0 0 0.4"/>
      <parent link="${prefix}link_5"/>
      <child link="${prefix}link_6"/>
      <axis xyz="0 1 0"/>
      <limit effort="40" lower="-2.0942" upper="2.0942" velocity="2.356"/>
  </joint>
  <joint name="${prefix}joint_a7" type="revolute">
      <origin rpy="0 0 0" xyz="0 0 0"/>
      <parent link="${prefix}link_6"/>
      <child link="${prefix}link_7"/>
      <axis xyz="0 0 1"/>
      <limit effort="40" lower="-3.0541" upper="3.0541" velocity="2.356"/>
  </joint>
  <joint name="${prefix}link7_to_tool0" type="fixed">
    <origin rpy="0 0 0" xyz="0 0 0.154"/>
    <parent link="${prefix}link_7"/>
    <child link="${prefix}tool0"/>
  </joint>

  <!-- fixed joint from tool0 to tcp (adjust xyz/rpy here to fine-tune alignment) -->
  <joint name="${prefix}tool0_to_tcp" type="fixed">
    <origin rpy="1.57 0 0" xyz="0 -0.05 0"/>
    <parent link="${prefix}tool0"/>
    <child link="${prefix}tcp"/>
  </joint>

  <!-- simple two-finger end-effector: left and right fingers attached to tcp -->
  <link name="${prefix}finger_left">
    <visual>
      <!-- finger is a thin rectangular box; tune size as needed -->
      <origin xyz="0 0 0" rpy="0 0 0"/>
      <geometry>
        <box size="0.02 0.08 0.02"/> <!-- x(width) y(thickness) z(length) -->
      </geometry>

        <color rgba="1 0.58 0.66 1"/>
    </visual>
    <collision>
      <origin xyz="0 0 0" rpy="0 0 0"/>
      <geometry>
        <box size="0.02 0.08 0.02"/>
      </geometry>
    </collision>
    <inertial>
      <origin xyz="0 0 0" rpy="0 0 0"/>
      <mass value="0.05"/>
      <inertia ixx="0.0001" ixy="0" ixz="0" iyy="0.0001" iyz="0" izz="0.0001"/>
    </inertial>
  </link>

  <link name="${prefix}finger_right">
     <material name="gray"/>
    <visual>
      <origin xyz="0 0 0" rpy="0 0 0"/>
      <geometry>
        <box size="0.02 0.08 0.02"/>
      </geometry>
    </visual>
    <collision>
      <origin xyz="0 0 0" rpy="0 0 0"/>
      <geometry>
        <box size="0.02 0.08 0.02"/>
      </geometry>
    </collision>
    <inertial>
      <origin xyz="0 0 0" rpy="0 0 0"/>
      <mass value="0.05"/>
      <inertia ixx="0.0001" ixy="0" ixz="0" iyy="0.0001" iyz="0" izz="0.0001"/>
    </inertial>
  </link>
    
  <joint name="${prefix}tcp_to_finger_left" type="prismatic">
    <origin xyz="0.01 0.12 -0.1" rpy="0 0 0"/>
    <parent link="${prefix}tcp"/>
    <child link="${prefix}finger_left"/>
      <axis xyz="0 0 -1" />
        <limit effort="20" lower="0.0" upper="0.04" velocity="0.2" />

  </joint>

  <joint name="${prefix}tcp_to_finger_right" type="prismatic">
    <origin xyz="0.01 0.12 0.0" rpy="0 0 0"/>
    <parent link="${prefix}tcp"/>
    <child link="${prefix}finger_right"/>
      <axis xyz="0 0 -1" />
        <limit effort="20" lower="0.0" upper="0.04" velocity="0.2" />

  </joint>
  

  </xacro:macro>
</robot>