<?xml version="1.0" ?>
<!-- =================================================================================== -->
<!-- |    This document was autogenerated by xacro from src/iiwa_description/urdf/dual_iiwa_robot.urdf.xacro | -->
<!-- |    EDITING THIS FILE BY HAND IS NOT RECOMMENDED                                 | -->
<!-- =================================================================================== -->
<robot name="dual_iiwa_robot">
  <!-- Left arm ros2_control system -->
  <ros2_control name="left_iiwa" type="system">
    <hardware>
      <plugin>mock_components/GenericSystem</plugin>
    </hardware>
    <!-- Left arm joints -->
    <joint name="left_joint_a1">
      <command_interface name="position"/>
      <state_interface name="position"/>
      <state_interface name="velocity"/>
    </joint>
    <joint name="left_joint_a2">
      <command_interface name="position"/>
      <state_interface name="position"/>
      <state_interface name="velocity"/>
    </joint>
    <joint name="left_joint_a3">
      <command_interface name="position"/>
      <state_interface name="position"/>
      <state_interface name="velocity"/>
    </joint>
    <joint name="left_joint_a4">
      <command_interface name="position"/>
      <state_interface name="position"/>
      <state_interface name="velocity"/>
    </joint>
    <joint name="left_joint_a5">
      <command_interface name="position"/>
      <state_interface name="position"/>
      <state_interface name="velocity"/>
    </joint>
    <joint name="left_joint_a6">
      <command_interface name="position"/>
      <state_interface name="position"/>
      <state_interface name="velocity"/>
    </joint>
    <joint name="left_joint_a7">
      <command_interface name="position"/>
      <state_interface name="position"/>
      <state_interface name="velocity"/>
    </joint>
  </ros2_control>
  <!-- Right arm ros2_control system -->
  <ros2_control name="right_iiwa" type="system">
    <hardware>
      <plugin>mock_components/GenericSystem</plugin>
    </hardware>
    <!-- Right arm joints -->
    <joint name="right_joint_a1">
      <command_interface name="position"/>
      <state_interface name="position"/>
      <state_interface name="velocity"/>
    </joint>
    <joint name="right_joint_a2">
      <command_interface name="position"/>
      <state_interface name="position"/>
      <state_interface name="velocity"/>
    </joint>
    <joint name="right_joint_a3">
      <command_interface name="position"/>
      <state_interface name="position"/>
      <state_interface name="velocity"/>
    </joint>
    <joint name="right_joint_a4">
      <command_interface name="position"/>
      <state_interface name="position"/>
      <state_interface name="velocity"/>
    </joint>
    <joint name="right_joint_a5">
      <command_interface name="position"/>
      <state_interface name="position"/>
      <state_interface name="velocity"/>
    </joint>
    <joint name="right_joint_a6">
      <command_interface name="position"/>
      <state_interface name="position"/>
      <state_interface name="velocity"/>
    </joint>
    <joint name="right_joint_a7">
      <command_interface name="position"/>
      <state_interface name="position"/>
      <state_interface name="velocity"/>
    </joint>
  </ros2_control>
  <material name="gray">
    <color rgba="0.5 0.5 0.5 1"/>
  </material>
  <!-- Distance from center to shoulders -->
  <!-- Materials -->
  <material name="torso_color">
    <color rgba="0.7 0.7 0.8 1"/>
  </material>
  <material name="mount_color">
    <color rgba="0.3 0.3 0.3 1.0"/>
  </material>
  <material name="dual_gray">
    <color rgba="0.5 0.5 0.5 1.0"/>
  </material>
  <!-- Base/World link -->
  <link name="world"/>
  <!-- Torso/Base link -->
  <link name="torso_base">
    <visual>
      <origin rpy="1.57 0 0" xyz="0 0 0"/>
      <geometry>
        <mesh filename="file:///home/nicola/Desktop/Progetto_Sapore/install/iiwa_description/share/iiwa_description/meshes/Busto.stl" scale="0.001 0.001 0.001"/>
      </geometry>
      <material name="torso_color"/>
    </visual>
    <collision>
      <origin rpy="1.57 0 0" xyz="0 0 0"/>
      <geometry>
        <mesh filename="file:///home/nicola/Desktop/Progetto_Sapore/install/iiwa_description/share/iiwa_description/meshes/Busto.stl" scale="0.001 0.001 0.001"/>
      </geometry>
    </collision>
    <inertial>
      <origin rpy="1.57 0 0" xyz="0 0 0"/>
      <mass value="50.0"/>
      <inertia ixx="4.0" ixy="0.0" ixz="0.0" iyy="3.0" iyz="0.0" izz="2.0"/>
    </inertial>
  </link>
  <!-- Joint connecting world to torso -->
  <joint name="world_to_torso" type="fixed">
    <parent link="world"/>
    <child link="torso_base"/>
    <!-- use robot_x/robot_y/robot_z properties to move the whole robot easily -->
    <origin rpy="0 0 0" xyz="-0.9 -0.43 0.462"/>
  </joint>
  <!-- Left shoulder mount -->
  <link name="left_shoulder_mount">
    <visual>
      <origin rpy="0 0 0" xyz="0 0 0"/>
      <geometry>
        <cylinder length="0.1" radius="0.05"/>
      </geometry>
      <material name="mount_color"/>
    </visual>
    <collision>
      <origin rpy="0 0 0" xyz="0 0 0"/>
      <geometry>
        <cylinder length="0.1" radius="0.05"/>
      </geometry>
    </collision>
    <inertial>
      <origin rpy="0 0 0" xyz="0 0 0"/>
      <mass value="2.0"/>
      <inertia ixx="0.1" ixy="0.0" ixz="0.0" iyy="0.1" iyz="0.0" izz="0.05"/>
    </inertial>
  </link>
  <link name="right_shoulder_mount">
    <visual>
      <origin rpy="0 0 0" xyz="0 0 0"/>
      <geometry>
        <cylinder length="0.1" radius="0.05"/>
      </geometry>
      <material name="mount_color"/>
    </visual>
    <collision>
      <origin rpy="0 0 0" xyz="0 0 0"/>
      <geometry>
        <cylinder length="0.1" radius="0.05"/>
      </geometry>
    </collision>
    <inertial>
      <origin rpy="0 0 0" xyz="0 0 0"/>
      <mass value="2.0"/>
      <inertia ixx="0.1" ixy="0.0" ixz="0.0" iyy="0.1" iyz="0.0" izz="0.05"/>
    </inertial>
  </link>
  <joint name="torso_to_left_shoulder" type="fixed">
    <parent link="torso_base"/>
    <child link="left_shoulder_mount"/>
    <!-- Left shoulder: ruotato di 90 gradi attorno Y per essere orizzontale, poi 90 attorno Z per puntare a sinistra -->
    <origin rpy="0 1.3735741213195374 1.5707963267948966" xyz="0 0.176 0.402"/>
  </joint>
  <!-- Joint connecting torso to right shoulder mount -->
  <joint name="torso_to_right_shoulder" type="fixed">
    <parent link="torso_base"/>
    <child link="right_shoulder_mount"/>
    <!-- Right shoulder: ruotato di 90 gradi attorno Y per essere orizzontale, poi -90 attorno Z per puntare a destra -->
    <origin rpy="0 1.3735741213195374 -1.5707963267948966" xyz="0 -0.176 0.402"/>
  </joint>
  <!-- Andiamo a definire la base del robot(prefix è un parametro che verra passato da dual_iiwa_robot per la costruzione del robot complessivo ) -->
  <link name="left_iiwa_base" type="fixed"/>
  <!-- Vado a definire il giunto che lega la spalla che può essere sinistra o destra con la base del manipolatore destro o sinistro-->
  <joint name="left_iiwa_root_joint" type="fixed">
    <origin rpy="0 0 0" xyz="0 0 0"/>
    <parent link="left_shoulder_mount"/>
    <child link="left_iiwa_base"/>
  </joint>
  <joint name="left_iiwa_base_joint" type="fixed">
    <origin rpy="0.0 0 0" xyz="0 0 0"/>
    <parent link="left_iiwa_base"/>
    <child link="left_link_0"/>
  </joint>
  <link name="left_link_0">
    <visual>
      <origin rpy="0.0 0 0" xyz="0 0 0"/>
      <geometry>
        <mesh filename="file:///home/nicola/Desktop/Progetto_Sapore/install/iiwa_description/share/iiwa_description/meshes/lbr_iiwa_14_r820/visual/base_link.dae"/>
      </geometry>
    </visual>
    <collision>
      <origin rpy="0 0 0" xyz="0 0 0"/>
      <geometry>
        <mesh filename="file:///home/nicola/Desktop/Progetto_Sapore/install/iiwa_description/share/iiwa_description/meshes/lbr_iiwa_14_r820/collision/base_link.stl"/>
      </geometry>
    </collision>
    <inertial>
      <origin rpy="0 0 0" xyz="-0.1 0 0.07"/>
      <mass value="5"/>
      <inertia ixx="0.05" ixy="0" ixz="0" iyy="0.06" iyz="0" izz="0.03"/>
    </inertial>
  </link>
  <link name="left_link_1">
    <visual>
      <origin rpy="0 0 0" xyz="0 0 0"/>
      <geometry>
        <mesh filename="file:///home/nicola/Desktop/Progetto_Sapore/install/iiwa_description/share/iiwa_description/meshes/lbr_iiwa_14_r820/visual/link_1.dae"/>
      </geometry>
    </visual>
    <collision>
      <origin rpy="0 0 0" xyz="0 0 0"/>
      <geometry>
        <mesh filename="file:///home/nicola/Desktop/Progetto_Sapore/install/iiwa_description/share/iiwa_description/meshes/lbr_iiwa_14_r820/collision/link_1.stl"/>
      </geometry>
    </collision>
    <inertial>
      <origin rpy="0 0 0" xyz="0 -0.03 0.12"/>
      <mass value="4"/>
      <inertia ixx="0.1" ixy="0" ixz="0" iyy="0.09" iyz="0" izz="0.02"/>
    </inertial>
  </link>
  <link name="left_link_2">
    <visual>
      <origin rpy="0 0 0" xyz="0 0 0"/>
      <geometry>
        <mesh filename="file:///home/nicola/Desktop/Progetto_Sapore/install/iiwa_description/share/iiwa_description/meshes/lbr_iiwa_14_r820/visual/link_2.dae"/>
      </geometry>
    </visual>
    <collision>
      <origin rpy="0 0 0" xyz="0 0 0"/>
      <geometry>
        <mesh filename="file:///home/nicola/Desktop/Progetto_Sapore/install/iiwa_description/share/iiwa_description/meshes/lbr_iiwa_14_r820/collision/link_2.stl"/>
      </geometry>
    </collision>
    <inertial>
      <origin rpy="0 0 0" xyz="0.0003 0.059 0.042"/>
      <mass value="4"/>
      <inertia ixx="0.05" ixy="0" ixz="0" iyy="0.018" iyz="0" izz="0.044"/>
    </inertial>
  </link>
  <link name="left_link_3">
    <visual>
      <origin rpy="0 0 0" xyz="0 0 0"/>
      <geometry>
        <mesh filename="file:///home/nicola/Desktop/Progetto_Sapore/install/iiwa_description/share/iiwa_description/meshes/lbr_iiwa_14_r820/visual/link_3.dae"/>
      </geometry>
    </visual>
    <collision>
      <origin rpy="0 0 0" xyz="0 0 0"/>
      <geometry>
        <mesh filename="file:///home/nicola/Desktop/Progetto_Sapore/install/iiwa_description/share/iiwa_description/meshes/lbr_iiwa_14_r820/collision/link_3.stl"/>
      </geometry>
    </collision>
    <inertial>
      <origin rpy="0 0 0" xyz="0 0.03 0.13"/>
      <mass value="3"/>
      <inertia ixx="0.08" ixy="0" ixz="0" iyy="0.075" iyz="0" izz="0.01"/>
    </inertial>
  </link>
  <link name="left_link_4">
    <visual>
      <origin rpy="0 0 0" xyz="0 0 0"/>
      <geometry>
        <mesh filename="file:///home/nicola/Desktop/Progetto_Sapore/install/iiwa_description/share/iiwa_description/meshes/lbr_iiwa_14_r820/visual/link_4.dae"/>
      </geometry>
    </visual>
    <collision>
      <origin rpy="0 0 0" xyz="0 0 0"/>
      <geometry>
        <mesh filename="file:///home/nicola/Desktop/Progetto_Sapore/install/iiwa_description/share/iiwa_description/meshes/lbr_iiwa_14_r820/collision/link_4.stl"/>
      </geometry>
    </collision>
    <inertial>
      <origin rpy="0 0 0" xyz="0 0.067 0.034"/>
      <mass value="2.7"/>
      <inertia ixx="0.03" ixy="0" ixz="0" iyy="0.01" iyz="0" izz="0.029"/>
    </inertial>
  </link>
  <link name="left_link_5">
    <visual>
      <origin rpy="0 0 0" xyz="0 0 0"/>
      <geometry>
        <mesh filename="file:///home/nicola/Desktop/Progetto_Sapore/install/iiwa_description/share/iiwa_description/meshes/lbr_iiwa_14_r820/visual/link_5.dae"/>
      </geometry>
    </visual>
    <collision>
      <origin rpy="0 0 0" xyz="0 0 0"/>
      <geometry>
        <mesh filename="file:///home/nicola/Desktop/Progetto_Sapore/install/iiwa_description/share/iiwa_description/meshes/lbr_iiwa_14_r820/collision/link_5.stl"/>
      </geometry>
    </collision>
    <inertial>
      <origin rpy="0 0 0" xyz="0.0001 0.021 0.076"/>
      <mass value="1.7"/>
      <inertia ixx="0.02" ixy="0" ixz="0" iyy="0.018" iyz="0" izz="0.005"/>
    </inertial>
  </link>
  <link name="left_link_6">
    <visual>
      <origin rpy="0 0 0" xyz="0 0 0"/>
      <geometry>
        <mesh filename="file:///home/nicola/Desktop/Progetto_Sapore/install/iiwa_description/share/iiwa_description/meshes/lbr_iiwa_14_r820/visual/link_6.dae"/>
      </geometry>
    </visual>
    <collision>
      <origin rpy="0 0 0" xyz="0 0 0"/>
      <geometry>
        <mesh filename="file:///home/nicola/Desktop/Progetto_Sapore/install/iiwa_description/share/iiwa_description/meshes/lbr_iiwa_14_r820/collision/link_6.stl"/>
      </geometry>
    </collision>
    <inertial>
      <origin rpy="0 0 0" xyz="0 0.0006 0.0004"/>
      <mass value="1.8"/>
      <inertia ixx="0.025" ixy="0" ixz="0" iyy="0.0136" iyz="0" izz="0.0247"/>
    </inertial>
  </link>
  <link name="left_link_7">
    <visual>
      <origin rpy="0 0 0" xyz="0 0 0.07"/>
      <material name="gray"/>
      <geometry>
        <mesh filename="file:///home/nicola/Desktop/Progetto_Sapore/install/iiwa_description/share/iiwa_description/meshes/lbr_iiwa_14_r820/visual/link_7_2.stl" scale="0.001 0.001 0.001"/>
      </geometry>
    </visual>
    <collision>
      <origin rpy="0 0 0" xyz="0 0 0.07"/>
      <geometry>
        <mesh filename="file:///home/nicola/Desktop/Progetto_Sapore/install/iiwa_description/share/iiwa_description/meshes/lbr_iiwa_14_r820/collision/link_7_2.stl" scale="0.001 0.001 0.001"/>
      </geometry>
    </collision>
    <inertial>
      <origin rpy="0 0 0" xyz="0 0 0.02"/>
      <mass value="0.42857142857142855"/>
      <inertia ixx="0.01" ixy="0" ixz="0" iyy="0.01" iyz="0" izz="0.01"/>
    </inertial>
  </link>
  <!-- intermediate tool0 link to make hand pose tunable -->
  <link name="left_tool0"/>
  <joint name="left_joint_a1" type="revolute">
    <origin rpy="0 0 0" xyz="0 0 0"/>
    <parent link="left_link_0"/>
    <child link="left_link_1"/>
    <axis xyz="0 0 1"/>
    <limit effort="320" lower="-2.9668" upper="2.9668" velocity="1.4834"/>
  </joint>
  <joint name="left_joint_a2" type="revolute">
    <origin rpy="0 0 0" xyz="-0.00043624 0 0.36"/>
    <parent link="left_link_1"/>
    <child link="left_link_2"/>
    <axis xyz="0 1 0"/>
    <limit effort="320" lower="-2.0942" upper="2.0942" velocity="1.4834"/>
  </joint>
  <joint name="left_joint_a3" type="revolute">
    <origin rpy="0 0 0" xyz="0 0 0"/>
    <parent link="left_link_2"/>
    <child link="left_link_3"/>
    <axis xyz="0 0 1"/>
    <limit effort="176" lower="-2.9668" upper="2.9668" velocity="1.7452"/>
  </joint>
  <joint name="left_joint_a4" type="revolute">
    <origin rpy="0 0 0" xyz="0.00043624 0 0.42"/>
    <parent link="left_link_3"/>
    <child link="left_link_4"/>
    <axis xyz="0 -1 0"/>
    <limit effort="176" lower="-2.0942" upper="2.0942" velocity="1.3089"/>
  </joint>
  <joint name="left_joint_a5" type="revolute">
    <origin rpy="0 0 0" xyz="0 0 0"/>
    <parent link="left_link_4"/>
    <child link="left_link_5"/>
    <axis xyz="0 0 1"/>
    <limit effort="110" lower="-2.9668" upper="2.9668" velocity="2.2688"/>
  </joint>
  <joint name="left_joint_a6" type="revolute">
    <origin rpy="0 0 0" xyz="0 0 0.4"/>
    <parent link="left_link_5"/>
    <child link="left_link_6"/>
    <axis xyz="0 1 0"/>
    <limit effort="40" lower="-2.0942" upper="2.0942" velocity="2.356"/>
  </joint>
  <joint name="left_joint_a7" type="revolute">
    <origin rpy="0 0 0" xyz="0 0 0"/>
    <parent link="left_link_6"/>
    <child link="left_link_7"/>
    <axis xyz="0 0 1"/>
    <limit effort="40" lower="-3.0541" upper="3.0541" velocity="2.356"/>
  </joint>
  <joint name="left_link7_to_tool0" type="fixed">
    <origin rpy="0 0 0" xyz="0 0 0.154"/>
    <parent link="left_link_7"/>
    <child link="left_tool0"/>
  </joint>
  <!--Ora dobbiamo aggiungere il tcp-->
  <link name="left_hand">
    <visual>
      <origin rpy="0 0 0.0" xyz="0 0 0"/>
      <geometry>
        <!-- SCHUNK end-effector mesh (file present in meshes/) -->
        <mesh filename="file:///home/nicola/Desktop/Progetto_Sapore/install/iiwa_description/share/iiwa_description/meshes/schunk.stl" scale="0.001 0.001 0.001"/>
      </geometry>
      <material name="gray"/>
    </visual>
    <collision>
      <origin rpy="0 0 0.0" xyz="0 0 0"/>
      <geometry>
        <mesh filename="file:///home/nicola/Desktop/Progetto_Sapore/install/iiwa_description/share/iiwa_description/meshes/schunk.stl" scale="0.001 0.001 0.001"/>
      </geometry>
    </collision>
    <inertial>
      <origin rpy="0 0 0.0" xyz="0 0 0"/>
      <mass value="0.5"/>
      <inertia ixx="0.0" ixy="0.0" ixz="0.0" iyy="0.0" iyz="0.0" izz="0.0"/>
    </inertial>
  </link>
  <joint name="left_tool0_to_hand" type="fixed">
    <origin rpy="0 0 0" xyz="0 0.0 0.06"/>
    <parent link="left_tool0"/>
    <child link="left_hand"/>
  </joint>
  <link name="left_finger_left">
    <material name="gray"/>
    <visual>
      <origin rpy="0 0 1.57" xyz="0 0 0"/>
      <geometry>
        <mesh filename="file:///home/nicola/Desktop/Progetto_Sapore/install/iiwa_description/share/iiwa_description/meshes/finger.stl" scale="0.001 0.001 0.001"/>
      </geometry>
      <material name="gray"/>
    </visual>
    <collision>
      <origin rpy="0 0 0" xyz="0 0 0.02"/>
      <geometry>
        <!-- Box semplice invece di mesh per collision più preciso -->
        <box size="0.015 0.02 0.10"/>
      </geometry>
    </collision>
    <inertial>
      <origin rpy="0 0 1.57" xyz="0 0 0"/>
      <mass value="0.05"/>
      <inertia ixx="0.0001" ixy="0" ixz="0" iyy="0.0001" iyz="0" izz="0.0001"/>
    </inertial>
  </link>
  <link name="left_finger_right">
    <visual>
      <origin rpy="0 0 1.57" xyz="0 0 0"/>
      <geometry>
        <mesh filename="file:///home/nicola/Desktop/Progetto_Sapore/install/iiwa_description/share/iiwa_description/meshes/finger.stl" scale="0.001 0.001 0.001"/>
      </geometry>
      <material name="gray"/>
    </visual>
    <collision>
      <origin rpy="0 0 0" xyz="0 0 0.02"/>
      <geometry>
        <!-- Box semplice invece di mesh per collision più preciso -->
        <box size="0.015 0.02 0.10"/>
      </geometry>
    </collision>
    <inertial>
      <origin rpy="0 0 1.57" xyz="0 0 0"/>
      <mass value="0.05"/>
      <inertia ixx="0.0001" ixy="0" ixz="0" iyy="0.0001" iyz="0" izz="0.0001"/>
    </inertial>
  </link>
  <joint name="left_hand_to_finger_left" type="prismatic">
    <origin rpy="0 0 0" xyz="0.017 0.064 0.10"/>
    <parent link="left_hand"/>
    <child link="left_finger_left"/>
    <axis xyz="0 -1 0"/>
    <limit effort="20" lower="0.0" upper="0.04" velocity="0.2"/>
  </joint>
  <joint name="left_hand_to_finger_right" type="prismatic">
    <origin rpy="0 0 0" xyz="0.016 -0.042 0.10"/>
    <parent link="left_hand"/>
    <child link="left_finger_right"/>
    <limit effort="20" lower="0.0" upper="0.04" velocity="0.2"/>
    <axis xyz="0 1 0"/>
    <mimic joint="left_hand_to_finger_left"/>
  </joint>
  <link name="left_tcp"> 
   </link>
  <joint name="left_hand_to_tcp" type="fixed">
    <origin rpy="0 0 0" xyz="0 0.0 0.12"/>
    <parent link="left_hand"/>
    <child link="left_tcp"/>
  </joint>
  <!-- Andiamo a definire la base del robot(prefix è un parametro che verra passato da dual_iiwa_robot per la costruzione del robot complessivo ) -->
  <link name="right_iiwa_base" type="fixed"/>
  <!-- Vado a definire il giunto che lega la spalla che può essere sinistra o destra con la base del manipolatore destro o sinistro-->
  <joint name="right_iiwa_root_joint" type="fixed">
    <origin rpy="0 0 0" xyz="0 0 0"/>
    <parent link="right_shoulder_mount"/>
    <child link="right_iiwa_base"/>
  </joint>
  <joint name="right_iiwa_base_joint" type="fixed">
    <origin rpy="0.0 0 0" xyz="0 0 0"/>
    <parent link="right_iiwa_base"/>
    <child link="right_link_0"/>
  </joint>
  <link name="right_link_0">
    <visual>
      <origin rpy="0.0 0 0" xyz="0 0 0"/>
      <geometry>
        <mesh filename="file:///home/nicola/Desktop/Progetto_Sapore/install/iiwa_description/share/iiwa_description/meshes/lbr_iiwa_14_r820/visual/base_link.dae"/>
      </geometry>
    </visual>
    <collision>
      <origin rpy="0 0 0" xyz="0 0 0"/>
      <geometry>
        <mesh filename="file:///home/nicola/Desktop/Progetto_Sapore/install/iiwa_description/share/iiwa_description/meshes/lbr_iiwa_14_r820/collision/base_link.stl"/>
      </geometry>
    </collision>
    <inertial>
      <origin rpy="0 0 0" xyz="-0.1 0 0.07"/>
      <mass value="5"/>
      <inertia ixx="0.05" ixy="0" ixz="0" iyy="0.06" iyz="0" izz="0.03"/>
    </inertial>
  </link>
  <link name="right_link_1">
    <visual>
      <origin rpy="0 0 0" xyz="0 0 0"/>
      <geometry>
        <mesh filename="file:///home/nicola/Desktop/Progetto_Sapore/install/iiwa_description/share/iiwa_description/meshes/lbr_iiwa_14_r820/visual/link_1.dae"/>
      </geometry>
    </visual>
    <collision>
      <origin rpy="0 0 0" xyz="0 0 0"/>
      <geometry>
        <mesh filename="file:///home/nicola/Desktop/Progetto_Sapore/install/iiwa_description/share/iiwa_description/meshes/lbr_iiwa_14_r820/collision/link_1.stl"/>
      </geometry>
    </collision>
    <inertial>
      <origin rpy="0 0 0" xyz="0 -0.03 0.12"/>
      <mass value="4"/>
      <inertia ixx="0.1" ixy="0" ixz="0" iyy="0.09" iyz="0" izz="0.02"/>
    </inertial>
  </link>
  <link name="right_link_2">
    <visual>
      <origin rpy="0 0 0" xyz="0 0 0"/>
      <geometry>
        <mesh filename="file:///home/nicola/Desktop/Progetto_Sapore/install/iiwa_description/share/iiwa_description/meshes/lbr_iiwa_14_r820/visual/link_2.dae"/>
      </geometry>
    </visual>
    <collision>
      <origin rpy="0 0 0" xyz="0 0 0"/>
      <geometry>
        <mesh filename="file:///home/nicola/Desktop/Progetto_Sapore/install/iiwa_description/share/iiwa_description/meshes/lbr_iiwa_14_r820/collision/link_2.stl"/>
      </geometry>
    </collision>
    <inertial>
      <origin rpy="0 0 0" xyz="0.0003 0.059 0.042"/>
      <mass value="4"/>
      <inertia ixx="0.05" ixy="0" ixz="0" iyy="0.018" iyz="0" izz="0.044"/>
    </inertial>
  </link>
  <link name="right_link_3">
    <visual>
      <origin rpy="0 0 0" xyz="0 0 0"/>
      <geometry>
        <mesh filename="file:///home/nicola/Desktop/Progetto_Sapore/install/iiwa_description/share/iiwa_description/meshes/lbr_iiwa_14_r820/visual/link_3.dae"/>
      </geometry>
    </visual>
    <collision>
      <origin rpy="0 0 0" xyz="0 0 0"/>
      <geometry>
        <mesh filename="file:///home/nicola/Desktop/Progetto_Sapore/install/iiwa_description/share/iiwa_description/meshes/lbr_iiwa_14_r820/collision/link_3.stl"/>
      </geometry>
    </collision>
    <inertial>
      <origin rpy="0 0 0" xyz="0 0.03 0.13"/>
      <mass value="3"/>
      <inertia ixx="0.08" ixy="0" ixz="0" iyy="0.075" iyz="0" izz="0.01"/>
    </inertial>
  </link>
  <link name="right_link_4">
    <visual>
      <origin rpy="0 0 0" xyz="0 0 0"/>
      <geometry>
        <mesh filename="file:///home/nicola/Desktop/Progetto_Sapore/install/iiwa_description/share/iiwa_description/meshes/lbr_iiwa_14_r820/visual/link_4.dae"/>
      </geometry>
    </visual>
    <collision>
      <origin rpy="0 0 0" xyz="0 0 0"/>
      <geometry>
        <mesh filename="file:///home/nicola/Desktop/Progetto_Sapore/install/iiwa_description/share/iiwa_description/meshes/lbr_iiwa_14_r820/collision/link_4.stl"/>
      </geometry>
    </collision>
    <inertial>
      <origin rpy="0 0 0" xyz="0 0.067 0.034"/>
      <mass value="2.7"/>
      <inertia ixx="0.03" ixy="0" ixz="0" iyy="0.01" iyz="0" izz="0.029"/>
    </inertial>
  </link>
  <link name="right_link_5">
    <visual>
      <origin rpy="0 0 0" xyz="0 0 0"/>
      <geometry>
        <mesh filename="file:///home/nicola/Desktop/Progetto_Sapore/install/iiwa_description/share/iiwa_description/meshes/lbr_iiwa_14_r820/visual/link_5.dae"/>
      </geometry>
    </visual>
    <collision>
      <origin rpy="0 0 0" xyz="0 0 0"/>
      <geometry>
        <mesh filename="file:///home/nicola/Desktop/Progetto_Sapore/install/iiwa_description/share/iiwa_description/meshes/lbr_iiwa_14_r820/collision/link_5.stl"/>
      </geometry>
    </collision>
    <inertial>
      <origin rpy="0 0 0" xyz="0.0001 0.021 0.076"/>
      <mass value="1.7"/>
      <inertia ixx="0.02" ixy="0" ixz="0" iyy="0.018" iyz="0" izz="0.005"/>
    </inertial>
  </link>
  <link name="right_link_6">
    <visual>
      <origin rpy="0 0 0" xyz="0 0 0"/>
      <geometry>
        <mesh filename="file:///home/nicola/Desktop/Progetto_Sapore/install/iiwa_description/share/iiwa_description/meshes/lbr_iiwa_14_r820/visual/link_6.dae"/>
      </geometry>
    </visual>
    <collision>
      <origin rpy="0 0 0" xyz="0 0 0"/>
      <geometry>
        <mesh filename="file:///home/nicola/Desktop/Progetto_Sapore/install/iiwa_description/share/iiwa_description/meshes/lbr_iiwa_14_r820/collision/link_6.stl"/>
      </geometry>
    </collision>
    <inertial>
      <origin rpy="0 0 0" xyz="0 0.0006 0.0004"/>
      <mass value="1.8"/>
      <inertia ixx="0.025" ixy="0" ixz="0" iyy="0.0136" iyz="0" izz="0.0247"/>
    </inertial>
  </link>
  <link name="right_link_7">
    <visual>
      <origin rpy="0 0 0" xyz="0 0 0.07"/>
      <material name="gray"/>
      <geometry>
        <mesh filename="file:///home/nicola/Desktop/Progetto_Sapore/install/iiwa_description/share/iiwa_description/meshes/lbr_iiwa_14_r820/visual/link_7_2.stl" scale="0.001 0.001 0.001"/>
      </geometry>
    </visual>
    <collision>
      <origin rpy="0 0 0" xyz="0 0 0.07"/>
      <geometry>
        <mesh filename="file:///home/nicola/Desktop/Progetto_Sapore/install/iiwa_description/share/iiwa_description/meshes/lbr_iiwa_14_r820/collision/link_7_2.stl" scale="0.001 0.001 0.001"/>
      </geometry>
    </collision>
    <inertial>
      <origin rpy="0 0 0" xyz="0 0 0.02"/>
      <mass value="0.42857142857142855"/>
      <!--this is for the MFT Pneumatisch flange-->
      <inertia ixx="0.01" ixy="0" ixz="0" iyy="0.01" iyz="0" izz="0.01"/>
    </inertial>
  </link>
  <!-- intermediate tool0 link to make hand pose tunable -->
  <link name="right_tool0"/>
  <joint name="right_joint_a1" type="revolute">
    <origin rpy="0 0 0" xyz="0 0 0"/>
    <parent link="right_link_0"/>
    <child link="right_link_1"/>
    <axis xyz="0 0 1"/>
    <limit effort="320" lower="-2.9668" upper="2.9668" velocity="1.4834"/>
  </joint>
  <joint name="right_joint_a2" type="revolute">
    <origin rpy="0 0 0" xyz="-0.00043624 0 0.36"/>
    <parent link="right_link_1"/>
    <child link="right_link_2"/>
    <axis xyz="0 1 0"/>
    <limit effort="320" lower="-2.0942" upper="2.0942" velocity="1.4834"/>
  </joint>
  <joint name="right_joint_a3" type="revolute">
    <origin rpy="0 0 0" xyz="0 0 0"/>
    <parent link="right_link_2"/>
    <child link="right_link_3"/>
    <axis xyz="0 0 1"/>
    <limit effort="176" lower="-2.9668" upper="2.9668" velocity="1.7452"/>
  </joint>
  <joint name="right_joint_a4" type="revolute">
    <origin rpy="0 0 0" xyz="0.00043624 0 0.42"/>
    <parent link="right_link_3"/>
    <child link="right_link_4"/>
    <axis xyz="0 -1 0"/>
    <limit effort="176" lower="-2.0942" upper="2.0942" velocity="1.3089"/>
  </joint>
  <joint name="right_joint_a5" type="revolute">
    <origin rpy="0 0 0" xyz="0 0 0"/>
    <parent link="right_link_4"/>
    <child link="right_link_5"/>
    <axis xyz="0 0 1"/>
    <limit effort="110" lower="-2.9668" upper="2.9668" velocity="2.2688"/>
  </joint>
  <joint name="right_joint_a6" type="revolute">
    <origin rpy="0 0 0" xyz="0 0 0.4"/>
    <parent link="right_link_5"/>
    <child link="right_link_6"/>
    <axis xyz="0 1 0"/>
    <limit effort="40" lower="-2.0942" upper="2.0942" velocity="2.356"/>
  </joint>
  <joint name="right_joint_a7" type="revolute">
    <origin rpy="0 0 0" xyz="0 0 0"/>
    <parent link="right_link_6"/>
    <child link="right_link_7"/>
    <axis xyz="0 0 1"/>
    <limit effort="40" lower="-3.0541" upper="3.0541" velocity="2.356"/>
  </joint>
  <joint name="right_link7_to_tool0" type="fixed">
    <origin rpy="0 0 0" xyz="0 0 0.154"/>
    <parent link="right_link_7"/>
    <child link="right_tool0"/>
  </joint>
  <!--Ora dobbiamo aggiungere il tcp-->
  <link name="right_hand">
    <visual>
      <origin rpy="0 0 0.0" xyz="0 0 0"/>
      <geometry>
        <!-- SCHUNK end-effector mesh (file present in meshes/) -->
        <mesh filename="file:///home/nicola/Desktop/Progetto_Sapore/install/iiwa_description/share/iiwa_description/meshes/schunk.stl" scale="0.001 0.001 0.001"/>
      </geometry>
      <material name="gray"/>
    </visual>
    <collision>
      <origin rpy="0 0 0.0" xyz="0 0 0"/>
      <geometry>
        <mesh filename="file:///home/nicola/Desktop/Progetto_Sapore/install/iiwa_description/share/iiwa_description/meshes/schunk.stl" scale="0.001 0.001 0.001"/>
      </geometry>
    </collision>
    <inertial>
      <origin rpy="0 0 0.0" xyz="0 0 0"/>
      <mass value="0.5"/>
      <inertia ixx="0.0" ixy="0.0" ixz="0.0" iyy="0.0" iyz="0.0" izz="0.0"/>
    </inertial>
  </link>
  <joint name="right_tool0_to_hand" type="fixed">
    <origin rpy="0 0 0" xyz="0 0.0 0.06"/>
    <parent link="right_tool0"/>
    <child link="right_hand"/>
  </joint>
  <link name="right_finger_left">
    <material name="gray"/>
    <visual>
      <origin rpy="0 0 1.57" xyz="0 0 0"/>
      <geometry>
        <mesh filename="file:///home/nicola/Desktop/Progetto_Sapore/install/iiwa_description/share/iiwa_description/meshes/finger.stl" scale="0.001 0.001 0.001"/>
      </geometry>
      <material name="gray"/>
    </visual>
    <collision>
      <origin rpy="0 0 0" xyz="0 0 0.02"/>
      <geometry>
        <!-- Box semplice invece di mesh per collision più preciso -->
        <box size="0.015 0.02 0.10"/>
      </geometry>
    </collision>
    <inertial>
      <origin rpy="0 0 1.57" xyz="0 0 0"/>
      <mass value="0.05"/>
      <inertia ixx="0.0001" ixy="0" ixz="0" iyy="0.0001" iyz="0" izz="0.0001"/>
    </inertial>
  </link>
  <link name="right_finger_right">
    <visual>
      <origin rpy="0 0 1.57" xyz="0 0 0"/>
      <geometry>
        <mesh filename="file:///home/nicola/Desktop/Progetto_Sapore/install/iiwa_description/share/iiwa_description/meshes/finger.stl" scale="0.001 0.001 0.001"/>
      </geometry>
      <material name="gray"/>
    </visual>
    <collision>
      <origin rpy="0 0 0" xyz="0 0 0.02"/>
      <geometry>
        <!-- Box semplice invece di mesh per collision più preciso -->
        <box size="0.015 0.02 0.10"/>
      </geometry>
    </collision>
    <inertial>
      <origin rpy="0 0 1.57" xyz="0 0 0"/>
      <mass value="0.05"/>
      <inertia ixx="0.0001" ixy="0" ixz="0" iyy="0.0001" iyz="0" izz="0.0001"/>
    </inertial>
  </link>
  <joint name="right_hand_to_finger_left" type="prismatic">
    <origin rpy="0 0 0" xyz="0.017 0.064 0.10"/>
    <parent link="right_hand"/>
    <child link="right_finger_left"/>
    <axis xyz="0 -1 0"/>
    <limit effort="20" lower="0.0" upper="0.04" velocity="0.2"/>
  </joint>
  <joint name="right_hand_to_finger_right" type="prismatic">
    <origin rpy="0 0 0" xyz="0.016 -0.042 0.10"/>
    <parent link="right_hand"/>
    <child link="right_finger_right"/>
    <limit effort="20" lower="0.0" upper="0.04" velocity="0.2"/>
    <axis xyz="0 1 0"/>
    <mimic joint="right_hand_to_finger_left"/>
  </joint>
  <link name="right_tcp"> 
   </link>
  <joint name="right_hand_to_tcp" type="fixed">
    <origin rpy="0 0 0" xyz="0 0.0 0.12"/>
    <parent link="right_hand"/>
    <child link="right_tcp"/>
  </joint>
</robot>
